2023-05-24 20:31:47 ERROR 500 response executing GraphQL.
2023-05-24 20:31:47 ERROR {"errors":[{"message":"Post \"http://anaconda2.default.svc.cluster.local/validate\": read tcp 10.52.98.5:37894-\u003e10.55.247.53:80: read: connection reset by peer","path":["upsertSweep"]}],"data":{"upsertSweep":null}}
2023-05-25 01:31:25 ERROR 400 response executing GraphQL.
2023-05-25 01:31:25 ERROR {"errors":[{"message":"Invalid sweep config: invalid hyperparameter configuration: after_grad_value_clip","path":["upsertSweep"]}],"data":{"upsertSweep":null}}
2023-05-25 01:31:25 ERROR Traceback (most recent call last):
  File "/Users/satoki/.pyenv/versions/3.10.4/lib/python3.10/site-packages/wandb/sdk/lib/retry.py", line 128, in __call__
    result = self._call_fn(*args, **kwargs)
  File "/Users/satoki/.pyenv/versions/3.10.4/lib/python3.10/site-packages/wandb/sdk/internal/internal_api.py", line 241, in execute
    return self.client.execute(*args, **kwargs)  # type: ignore
  File "/Users/satoki/.pyenv/versions/3.10.4/lib/python3.10/site-packages/wandb/vendor/gql-0.2.0/wandb_gql/client.py", line 52, in execute
    result = self._get_result(document, *args, **kwargs)
  File "/Users/satoki/.pyenv/versions/3.10.4/lib/python3.10/site-packages/wandb/vendor/gql-0.2.0/wandb_gql/client.py", line 60, in _get_result
    return self.transport.execute(document, *args, **kwargs)
  File "/Users/satoki/.pyenv/versions/3.10.4/lib/python3.10/site-packages/wandb/vendor/gql-0.2.0/wandb_gql/transport/requests.py", line 39, in execute
    request.raise_for_status()
  File "/Users/satoki/.pyenv/versions/3.10.4/lib/python3.10/site-packages/requests/models.py", line 1021, in raise_for_status
    raise HTTPError(http_error_msg, response=self)
requests.exceptions.HTTPError: 400 Client Error: Bad Request for url: https://api.wandb.ai/graphql

During handling of the above exception, another exception occurred:

Traceback (most recent call last):
  File "/Users/satoki/.pyenv/versions/3.10.4/lib/python3.10/site-packages/wandb/apis/normalize.py", line 26, in wrapper
    return func(*args, **kwargs)
  File "/Users/satoki/.pyenv/versions/3.10.4/lib/python3.10/site-packages/wandb/sdk/internal/internal_api.py", line 2295, in upsert_sweep
    raise e
  File "/Users/satoki/.pyenv/versions/3.10.4/lib/python3.10/site-packages/wandb/sdk/internal/internal_api.py", line 2280, in upsert_sweep
    response = self.gql(
  File "/Users/satoki/.pyenv/versions/3.10.4/lib/python3.10/site-packages/wandb/sdk/internal/internal_api.py", line 213, in gql
    ret = self._retry_gql(
  File "/Users/satoki/.pyenv/versions/3.10.4/lib/python3.10/site-packages/wandb/sdk/lib/retry.py", line 144, in __call__
    retry_timedelta_triggered = check_retry_fn(e)
  File "/Users/satoki/.pyenv/versions/3.10.4/lib/python3.10/site-packages/wandb/util.py", line 990, in no_retry_4xx
    raise UsageError(body["errors"][0]["message"])
wandb.errors.UsageError: Invalid sweep config: invalid hyperparameter configuration: after_grad_value_clip

During handling of the above exception, another exception occurred:

Traceback (most recent call last):
  File "/Users/satoki/.pyenv/versions/3.10.4/lib/python3.10/site-packages/wandb/cli/cli.py", line 102, in wrapper
    return func(*args, **kwargs)
  File "/Users/satoki/.pyenv/versions/3.10.4/lib/python3.10/site-packages/wandb/cli/cli.py", line 957, in sweep
    sweep_id, warnings = api.upsert_sweep(
  File "/Users/satoki/.pyenv/versions/3.10.4/lib/python3.10/site-packages/wandb/apis/internal.py", line 102, in upsert_sweep
    return self.api.upsert_sweep(*args, **kwargs)
  File "/Users/satoki/.pyenv/versions/3.10.4/lib/python3.10/site-packages/wandb/apis/normalize.py", line 64, in wrapper
    raise CommError(message, err).with_traceback(sys.exc_info()[2])
  File "/Users/satoki/.pyenv/versions/3.10.4/lib/python3.10/site-packages/wandb/apis/normalize.py", line 26, in wrapper
    return func(*args, **kwargs)
  File "/Users/satoki/.pyenv/versions/3.10.4/lib/python3.10/site-packages/wandb/sdk/internal/internal_api.py", line 2295, in upsert_sweep
    raise e
  File "/Users/satoki/.pyenv/versions/3.10.4/lib/python3.10/site-packages/wandb/sdk/internal/internal_api.py", line 2280, in upsert_sweep
    response = self.gql(
  File "/Users/satoki/.pyenv/versions/3.10.4/lib/python3.10/site-packages/wandb/sdk/internal/internal_api.py", line 213, in gql
    ret = self._retry_gql(
  File "/Users/satoki/.pyenv/versions/3.10.4/lib/python3.10/site-packages/wandb/sdk/lib/retry.py", line 144, in __call__
    retry_timedelta_triggered = check_retry_fn(e)
  File "/Users/satoki/.pyenv/versions/3.10.4/lib/python3.10/site-packages/wandb/util.py", line 990, in no_retry_4xx
    raise UsageError(body["errors"][0]["message"])
wandb.errors.CommError: Invalid sweep config: invalid hyperparameter configuration: after_grad_value_clip

